<sdf version='1.6'>
  <world name='default'>
    <light name='sun' type='directional'>
      <cast_shadows>1</cast_shadows>
      <pose frame=''>0 0 10 0 -0 0</pose>
      <diffuse>0.8 0.8 0.8 1</diffuse>
      <specular>0.2 0.2 0.2 1</specular>
      <attenuation>
        <range>1000</range>
        <constant>0.9</constant>
        <linear>0.01</linear>
        <quadratic>0.001</quadratic>
      </attenuation>
      <direction>-0.5 0.1 -0.9</direction>
    </light>
    <model name='ground_plane'>
      <static>1</static>
      <link name='link'>
        <collision name='collision'>
          <geometry>
            <plane>
              <normal>0 0 1</normal>
              <size>100 100</size>
            </plane>
          </geometry>
          <surface>
            <friction>
              <ode>
                <mu>100</mu>
                <mu2>50</mu2>
              </ode>
              <torsional>
                <ode/>
              </torsional>
            </friction>
            <contact>
              <ode/>
            </contact>
            <bounce/>
          </surface>
          <max_contacts>10</max_contacts>
        </collision>
        <visual name='visual'>
          <cast_shadows>0</cast_shadows>
          <geometry>
            <plane>
              <normal>0 0 1</normal>
              <size>100 100</size>
            </plane>
          </geometry>
          <material>
            <script>
              <uri>file://media/materials/scripts/gazebo.material</uri>
              <name>Gazebo/Grey</name>
            </script>
          </material>
        </visual>
        <self_collide>0</self_collide>
        <enable_wind>0</enable_wind>
        <kinematic>0</kinematic>
      </link>
    </model>
    <gravity>0 0 -9.8</gravity>
    <magnetic_field>6e-06 2.3e-05 -4.2e-05</magnetic_field>
    <atmosphere type='adiabatic'/>
    <physics name='default_physics' default='0' type='ode'>
      <max_step_size>0.001</max_step_size>
      <real_time_factor>1</real_time_factor>
      <real_time_update_rate>1000</real_time_update_rate>
    </physics>
    <scene>
      <ambient>0.4 0.4 0.4 1</ambient>
      <background>0.7 0.7 0.7 1</background>
      <shadows>1</shadows>
    </scene>
    <audio>
      <device>default</device>
    </audio>
    <wind/>
    <spherical_coordinates>
      <surface_model>EARTH_WGS84</surface_model>
      <latitude_deg>0</latitude_deg>
      <longitude_deg>0</longitude_deg>
      <elevation>0</elevation>
      <heading_deg>0</heading_deg>
    </spherical_coordinates>
    <model name='youbot'>
      <link name='base_link'>
        <pose frame=''>0 0 0 0 -0 0</pose>
        <inertial>
          <pose frame=''>-0.030793 0.000337 -0.000871 0 -0 0</pose>
          <mass>11.565</mass>
          <inertia>
            <ixx>0.79805</ixx>
            <ixy>0.00175012</ixy>
            <ixz>-0.00672532</ixz>
            <iyy>0.963169</iyy>
            <iyz>-0.00203338</iyz>
            <izz>0.875828</izz>
          </inertia>
        </inertial>
        <collision name='base_link_fixed_joint_lump__arm_link_0_collision'>
          <pose frame=''>0 0 0 0 -0 0</pose>
          <geometry>
            <mesh>
              <scale>1 1 1</scale>
              <uri>/home/danil/ros_lib_ws/src/youbot_description/meshes/youbot_arm/arm0_convex.dae</uri>
            </mesh>
          </geometry>
          <surface>
            <contact>
              <ode/>
            </contact>
            <friction>
              <ode/>
              <torsional>
                <ode/>
              </torsional>
            </friction>
            <bounce/>
          </surface>
          <max_contacts>10</max_contacts>
        </collision>
        <collision name='base_link_fixed_joint_lump__camera_tower_link_collision_1'>
          <pose frame=''>-0.5 0 0.245 0 -0 0</pose>
          <geometry>
            <box>
              <size>0.03 0.03 0.49</size>
            </box>
          </geometry>
          <max_contacts>10</max_contacts>
          <surface>
            <contact>
              <ode/>
            </contact>
            <bounce/>
            <friction>
              <torsional>
                <ode/>
              </torsional>
              <ode/>
            </friction>
          </surface>
        </collision>
        <collision name='base_link_fixed_joint_lump__tower_cam3d_foot_link_collision_2'>
          <pose frame=''>-0.49 0 0.49 1.5708 -0 1.5708</pose>
          <geometry>
            <mesh>
              <scale>0.0004 0.0007 0.001</scale>
              <uri>/home/danil/ros_lib_ws/src/youbot_description/meshes/sensors/asus_xtion_pro_live_base.dae</uri>
            </mesh>
          </geometry>
          <max_contacts>10</max_contacts>
          <surface>
            <contact>
              <ode/>
            </contact>
            <bounce/>
            <friction>
              <torsional>
                <ode/>
              </torsional>
              <ode/>
            </friction>
          </surface>
        </collision>
        <collision name='base_link_fixed_joint_lump__tower_cam3d_tilt_link_collision_3'>
          <pose frame=''>-0.496404 0 0.504082 0 0.5 0</pose>
          <geometry>
            <cylinder>
              <length>0.025</length>
              <radius>0.005</radius>
            </cylinder>
          </geometry>
          <max_contacts>10</max_contacts>
          <surface>
            <contact>
              <ode/>
            </contact>
            <bounce/>
            <friction>
              <torsional>
                <ode/>
              </torsional>
              <ode/>
            </friction>
          </surface>
        </collision>
        <collision name='base_link_fixed_joint_lump__tower_cam3d_camera_collision_4'>
          <pose frame=''>-0.468066 0 0.514239 2.0708 -0 1.5708</pose>
          <geometry>
            <mesh>
              <scale>0.001 0.001 0.001</scale>
              <uri>/home/danil/ros_lib_ws/src/youbot_description/meshes/sensors/asus_xtion_pro_live_camera.dae</uri>
            </mesh>
          </geometry>
          <max_contacts>10</max_contacts>
          <surface>
            <contact>
              <ode/>
            </contact>
            <bounce/>
            <friction>
              <torsional>
                <ode/>
              </torsional>
              <ode/>
            </friction>
          </surface>
        </collision>
        <visual name='base_link_fixed_joint_lump__arm_link_0_visual'>
          <pose frame=''>0 0 0 0 -0 0</pose>
          <geometry>
            <mesh>
              <scale>1 1 1</scale>
              <uri>/home/danil/ros_lib_ws/src/youbot_description/meshes/youbot_arm/arm0.dae</uri>
            </mesh>
          </geometry>
          <material>
            <script>
              <name>youbot/DarkGrey</name>
              <uri>file://media/materials/scripts/gazebo.material</uri>
            </script>
          </material>
        </visual>
        <visual name='base_link_fixed_joint_lump__camera_tower_link_visual_1'>
          <pose frame=''>-0.5 0 0.245 0 -0 0</pose>
          <geometry>
            <box>
              <size>0.03 0.03 0.49</size>
            </box>
          </geometry>
        </visual>
        <visual name='base_link_fixed_joint_lump__tower_cam3d_foot_link_visual_2'>
          <pose frame=''>-0.49 0 0.49 1.5708 -0 1.5708</pose>
          <geometry>
            <mesh>
              <scale>0.0004 0.0007 0.001</scale>
              <uri>/home/danil/ros_lib_ws/src/youbot_description/meshes/sensors/asus_xtion_pro_live_base.dae</uri>
            </mesh>
          </geometry>
        </visual>
        <visual name='base_link_fixed_joint_lump__tower_cam3d_tilt_link_visual_3'>
          <pose frame=''>-0.496404 0 0.504082 0 0.5 0</pose>
          <geometry>
            <cylinder>
              <length>0.025</length>
              <radius>0.005</radius>
            </cylinder>
          </geometry>
        </visual>
        <visual name='base_link_fixed_joint_lump__tower_cam3d_camera_visual_4'>
          <pose frame=''>-0.468066 0 0.514239 2.0708 -0 1.5708</pose>
          <geometry>
            <mesh>
              <scale>0.001 0.001 0.001</scale>
              <uri>/home/danil/ros_lib_ws/src/youbot_description/meshes/sensors/asus_xtion_pro_live_camera.dae</uri>
            </mesh>
          </geometry>
        </visual>
        <velocity_decay/>
        <velocity_decay/>
        <gravity>1</gravity>
        <velocity_decay/>
        <self_collide>0</self_collide>
        <enable_wind>0</enable_wind>
        <kinematic>0</kinematic>
      </link>
      <link name='arm_link_1'>
        <pose frame=''>0.024 0 0.096 0 -0 2.96706</pose>
        <inertial>
          <pose frame=''>0.01489 0.00213 0.00213 0 -0 0</pose>
          <mass>2.412</mass>
          <inertia>
            <ixx>0.003863</ixx>
            <ixy>-0.000979</ixy>
            <ixz>0</ixz>
            <iyy>0.006196</iyy>
            <iyz>0</iyz>
            <izz>0.006369</izz>
          </inertia>
        </inertial>
        <collision name='arm_link_1_collision'>
          <pose frame=''>0 0 0 0 -0 0</pose>
          <geometry>
            <mesh>
              <scale>1 1 1</scale>
              <uri>/home/danil/ros_lib_ws/src/youbot_description/meshes/youbot_arm/arm1_convex.dae</uri>
            </mesh>
          </geometry>
          <surface>
            <contact>
              <ode/>
            </contact>
            <friction>
              <ode/>
              <torsional>
                <ode/>
              </torsional>
            </friction>
            <bounce/>
          </surface>
          <max_contacts>10</max_contacts>
        </collision>
        <visual name='arm_link_1_visual'>
          <pose frame=''>0 0 0 0 -0 0</pose>
          <geometry>
            <mesh>
              <scale>1 1 1</scale>
              <uri>/home/danil/ros_lib_ws/src/youbot_description/meshes/youbot_arm/arm1.dae</uri>
            </mesh>
          </geometry>
          <material>
            <script>
              <uri>__default__</uri>
              <name>__default__</name>
            </script>
          </material>
        </visual>
        <gravity>1</gravity>
        <velocity_decay/>
        <self_collide>0</self_collide>
        <enable_wind>0</enable_wind>
        <kinematic>0</kinematic>
      </link>
      <joint name='arm_joint_1' type='revolute'>
        <child>arm_link_1</child>
        <parent>base_link</parent>
        <axis>
          <xyz>0 0 -1</xyz>
          <limit>
            <lower>0</lower>
            <upper>5.89921</upper>
            <effort>9.5</effort>
            <velocity>1.5708</velocity>
          </limit>
          <dynamics>
            <damping>1</damping>
            <friction>1</friction>
            <spring_reference>0</spring_reference>
            <spring_stiffness>0</spring_stiffness>
          </dynamics>
          <use_parent_model_frame>1</use_parent_model_frame>
        </axis>
      </joint>
      <link name='arm_link_2'>
        <pose frame=''>-0.008499 0.00573 0.115 0 -1.13446 2.96706</pose>
        <inertial>
          <pose frame=''>0.10453 0.0017 -0.00297 0 -0 0</pose>
          <mass>1.155</mass>
          <inertia>
            <ixx>0.000823</ixx>
            <ixy>0</ixy>
            <ixz>-0</ixz>
            <iyy>0.004447</iyy>
            <iyz>0</iyz>
            <izz>0.004439</izz>
          </inertia>
        </inertial>
        <collision name='arm_link_2_collision'>
          <pose frame=''>0 -0.032 0.078 0 -0 0</pose>
          <geometry>
            <mesh>
              <scale>1 1 1</scale>
              <uri>/home/danil/ros_lib_ws/src/youbot_description/meshes/youbot_arm/arm2_convex.dae</uri>
            </mesh>
          </geometry>
          <surface>
            <contact>
              <ode/>
            </contact>
            <friction>
              <ode/>
              <torsional>
                <ode/>
              </torsional>
            </friction>
            <bounce/>
          </surface>
          <max_contacts>10</max_contacts>
        </collision>
        <visual name='arm_link_2_visual'>
          <pose frame=''>0 -0.032 0.078 0 -0 0</pose>
          <geometry>
            <mesh>
              <scale>1 1 1</scale>
              <uri>/home/danil/ros_lib_ws/src/youbot_description/meshes/youbot_arm/arm2.dae</uri>
            </mesh>
          </geometry>
          <material>
            <script>
              <uri>__default__</uri>
              <name>__default__</name>
            </script>
          </material>
        </visual>
        <gravity>1</gravity>
        <velocity_decay/>
        <self_collide>0</self_collide>
        <enable_wind>0</enable_wind>
        <kinematic>0</kinematic>
      </link>
      <joint name='arm_joint_2' type='revolute'>
        <child>arm_link_2</child>
        <parent>arm_link_1</parent>
        <axis>
          <xyz>-0.173648 -0.984808 0</xyz>
          <limit>
            <lower>0</lower>
            <upper>2.70526</upper>
            <effort>9.5</effort>
            <velocity>1.5708</velocity>
          </limit>
          <dynamics>
            <damping>1</damping>
            <friction>1</friction>
            <spring_reference>0</spring_reference>
            <spring_stiffness>0</spring_stiffness>
          </dynamics>
          <use_parent_model_frame>1</use_parent_model_frame>
        </axis>
      </joint>
      <link name='arm_link_3'>
        <pose frame=''>0.129845 -0.018663 0.180506 -0 1.41372 2.96706</pose>
        <inertial>
          <pose frame=''>0.0001 0.0967 0.02107 0 -0 0</pose>
          <mass>0.934</mass>
          <inertia>
            <ixx>0.002459</ixx>
            <ixy>0</ixy>
            <ixz>0</ixz>
            <iyy>0.002571</iyy>
            <iyz>-0</iyz>
            <izz>0.000535</izz>
          </inertia>
        </inertial>
        <collision name='arm_link_3_collision'>
          <pose frame=''>0 0.028 0.079 0 -0 0</pose>
          <geometry>
            <mesh>
              <scale>1 1 1</scale>
              <uri>/home/danil/ros_lib_ws/src/youbot_description/meshes/youbot_arm/arm3_convex.dae</uri>
            </mesh>
          </geometry>
          <surface>
            <contact>
              <ode/>
            </contact>
            <friction>
              <ode/>
              <torsional>
                <ode/>
              </torsional>
            </friction>
            <bounce/>
          </surface>
          <max_contacts>10</max_contacts>
        </collision>
        <visual name='arm_link_3_visual'>
          <pose frame=''>0 0.028 0.079 0 -0 0</pose>
          <geometry>
            <mesh>
              <scale>1 1 1</scale>
              <uri>/home/danil/ros_lib_ws/src/youbot_description/meshes/youbot_arm/arm3.dae</uri>
            </mesh>
          </geometry>
          <material>
            <script>
              <uri>__default__</uri>
              <name>__default__</name>
            </script>
          </material>
        </visual>
        <gravity>1</gravity>
        <velocity_decay/>
        <self_collide>0</self_collide>
        <enable_wind>0</enable_wind>
        <kinematic>0</kinematic>
      </link>
      <joint name='arm_joint_3' type='revolute'>
        <child>arm_link_3</child>
        <parent>arm_link_2</parent>
        <axis>
          <xyz>-0.173648 -0.984808 0</xyz>
          <limit>
            <lower>-5.18363</lower>
            <upper>0</upper>
            <effort>6</effort>
            <velocity>1.5708</velocity>
          </limit>
          <dynamics>
            <damping>1</damping>
            <friction>1</friction>
            <spring_reference>0</spring_reference>
            <spring_stiffness>0</spring_stiffness>
          </dynamics>
          <use_parent_model_frame>1</use_parent_model_frame>
        </axis>
      </joint>
      <link name='arm_link_4'>
        <pose frame=''>-0.001467 0.004491 0.201624 0 -0.375246 2.96706</pose>
        <inertial>
          <pose frame=''>0.00011 0.05103 -0.02319 0 -0 0</pose>
          <mass>0.877</mass>
          <inertia>
            <ixx>0.000869</ixx>
            <ixy>0</ixy>
            <ixz>-0</ixz>
            <iyy>0.001173</iyy>
            <iyz>-0.000231</iyz>
            <izz>0.001091</izz>
          </inertia>
        </inertial>
        <collision name='arm_link_4_collision'>
          <pose frame=''>0 -0.01 0.029 0 -0 0</pose>
          <geometry>
            <mesh>
              <scale>1 1 1</scale>
              <uri>/home/danil/ros_lib_ws/src/youbot_description/meshes/youbot_arm/arm4_convex.dae</uri>
            </mesh>
          </geometry>
          <surface>
            <contact>
              <ode/>
            </contact>
            <friction>
              <ode/>
              <torsional>
                <ode/>
              </torsional>
            </friction>
            <bounce/>
          </surface>
          <max_contacts>10</max_contacts>
        </collision>
        <visual name='arm_link_4_visual'>
          <pose frame=''>0 -0.01 0.029 0 -0 0</pose>
          <geometry>
            <mesh>
              <scale>1 1 1</scale>
              <uri>/home/danil/ros_lib_ws/src/youbot_description/meshes/youbot_arm/arm4.dae</uri>
            </mesh>
          </geometry>
          <material>
            <script>
              <uri>__default__</uri>
              <name>__default__</name>
            </script>
          </material>
        </visual>
        <gravity>1</gravity>
        <velocity_decay/>
        <self_collide>0</self_collide>
        <enable_wind>0</enable_wind>
        <kinematic>0</kinematic>
      </link>
      <joint name='arm_joint_4' type='revolute'>
        <child>arm_link_4</child>
        <parent>arm_link_3</parent>
        <axis>
          <xyz>-0.173648 -0.984808 0</xyz>
          <limit>
            <lower>0</lower>
            <upper>3.57792</upper>
            <effort>2</effort>
            <velocity>1.5708</velocity>
          </limit>
          <dynamics>
            <damping>1</damping>
            <friction>1</friction>
            <spring_reference>0</spring_reference>
            <spring_stiffness>0</spring_stiffness>
          </dynamics>
          <use_parent_model_frame>1</use_parent_model_frame>
        </axis>
      </joint>
      <link name='arm_link_5'>
        <pose frame=''>0.047287 -0.004106 0.321846 -0.085052 0.365926 -0.408446</pose>
        <inertial>
          <pose frame=''>0 0.000822 -0.012035 0 -0 0</pose>
          <mass>0.351</mass>
          <inertia>
            <ixx>0.0103003</ixx>
            <ixy>0</ixy>
            <ixz>0</ixz>
            <iyy>0.0103593</iyy>
            <iyz>1.38404e-06</iyz>
            <izz>0.0101191</izz>
          </inertia>
        </inertial>
        <collision name='arm_link_5_collision'>
          <pose frame=''>0.003 0 -0.034 0 -0 0</pose>
          <geometry>
            <mesh>
              <scale>1 1 1</scale>
              <uri>/home/danil/ros_lib_ws/src/youbot_description/meshes/youbot_arm/arm5_convex.dae</uri>
            </mesh>
          </geometry>
          <surface>
            <contact>
              <ode/>
            </contact>
            <friction>
              <ode/>
              <torsional>
                <ode/>
              </torsional>
            </friction>
            <bounce/>
          </surface>
          <max_contacts>10</max_contacts>
        </collision>
        <collision name='arm_link_5_fixed_joint_lump__gripper_palm_link_collision_1'>
          <pose frame=''>0 0 0 0 -0 0</pose>
          <geometry>
            <mesh>
              <scale>1 1 1</scale>
              <uri>/home/danil/ros_lib_ws/src/youbot_description/meshes/youbot_gripper/palm_convex.dae</uri>
            </mesh>
          </geometry>
          <surface>
            <contact>
              <ode/>
            </contact>
            <friction>
              <ode/>
              <torsional>
                <ode/>
              </torsional>
            </friction>
            <bounce/>
          </surface>
          <max_contacts>10</max_contacts>
        </collision>
        <visual name='arm_link_5_visual'>
          <pose frame=''>0.003 0 -0.034 0 -0 0</pose>
          <geometry>
            <mesh>
              <scale>1 1 1</scale>
              <uri>/home/danil/ros_lib_ws/src/youbot_description/meshes/youbot_arm/arm5.dae</uri>
            </mesh>
          </geometry>
          <material>
            <script>
              <uri>__default__</uri>
              <name>__default__</name>
            </script>
          </material>
        </visual>
        <visual name='arm_link_5_fixed_joint_lump__gripper_palm_link_visual_1'>
          <pose frame=''>0 0 0 0 -0 0</pose>
          <geometry>
            <mesh>
              <scale>1 1 1</scale>
              <uri>/home/danil/ros_lib_ws/src/youbot_description/meshes/youbot_gripper/palm.dae</uri>
            </mesh>
          </geometry>
          <material>
            <script>
              <name>Gazebo/Black</name>
              <uri>file://media/materials/scripts/gazebo.material</uri>
            </script>
          </material>
        </visual>
        <velocity_decay/>
        <gravity>1</gravity>
        <velocity_decay/>
        <self_collide>1</self_collide>
        <enable_wind>0</enable_wind>
        <kinematic>0</kinematic>
      </link>
      <joint name='arm_joint_5' type='revolute'>
        <child>arm_link_5</child>
        <parent>arm_link_4</parent>
        <axis>
          <xyz>-0.360933 0.063642 -0.930418</xyz>
          <limit>
            <lower>0</lower>
            <upper>5.84685</upper>
            <effort>1</effort>
            <velocity>1.5708</velocity>
          </limit>
          <dynamics>
            <damping>1</damping>
            <friction>1</friction>
            <spring_reference>0</spring_reference>
            <spring_stiffness>0</spring_stiffness>
          </dynamics>
          <use_parent_model_frame>1</use_parent_model_frame>
        </axis>
      </joint>
      <link name='gripper_finger_link_l'>
        <pose frame=''>0.07026 -0.001105 0.362579 0.085052 -0.365926 2.73315</pose>
        <inertial>
          <pose frame=''>0 -0.001 0 0 -0 0</pose>
          <mass>0.01</mass>
          <inertia>
            <ixx>0.01</ixx>
            <ixy>0</ixy>
            <ixz>0</ixz>
            <iyy>0.01</iyy>
            <iyz>0</iyz>
            <izz>0.01</izz>
          </inertia>
        </inertial>
        <collision name='gripper_finger_link_l_collision'>
          <pose frame=''>0 0 0 0 -0 0</pose>
          <geometry>
            <mesh>
              <scale>1 1 1</scale>
              <uri>/home/danil/ros_lib_ws/src/youbot_description/meshes/youbot_gripper/finger_convex.dae</uri>
            </mesh>
          </geometry>
          <max_contacts>10</max_contacts>
          <surface>
            <contact>
              <ode/>
            </contact>
            <bounce/>
            <friction>
              <torsional>
                <ode/>
              </torsional>
              <ode/>
            </friction>
          </surface>
        </collision>
        <visual name='gripper_finger_link_l_visual'>
          <pose frame=''>0 0 0 0 -0 0</pose>
          <geometry>
            <mesh>
              <scale>1 1 1</scale>
              <uri>/home/danil/ros_lib_ws/src/youbot_description/meshes/youbot_gripper/finger.dae</uri>
            </mesh>
          </geometry>
        </visual>
        <self_collide>0</self_collide>
        <enable_wind>0</enable_wind>
        <kinematic>0</kinematic>
      </link>
      <joint name='gripper_finger_joint_l' type='prismatic'>
        <child>gripper_finger_link_l</child>
        <parent>arm_link_5</parent>
        <axis>
          <xyz>0.367852 0.926495 -0.079325</xyz>
          <limit>
            <lower>0</lower>
            <upper>0.0115</upper>
            <effort>1</effort>
            <velocity>0.1</velocity>
          </limit>
          <dynamics>
            <damping>1</damping>
            <friction>1</friction>
            <spring_reference>0</spring_reference>
            <spring_stiffness>0</spring_stiffness>
          </dynamics>
          <use_parent_model_frame>1</use_parent_model_frame>
        </axis>
      </joint>
      <link name='gripper_finger_link_r'>
        <pose frame=''>0.064375 -0.015929 0.363848 -0.085052 0.365926 -0.408446</pose>
        <inertial>
          <pose frame=''>0 -0.001 0 0 -0 0</pose>
          <mass>0.01</mass>
          <inertia>
            <ixx>0.01</ixx>
            <ixy>0</ixy>
            <ixz>0</ixz>
            <iyy>0.01</iyy>
            <iyz>0</iyz>
            <izz>0.01</izz>
          </inertia>
        </inertial>
        <collision name='gripper_finger_link_r_collision'>
          <pose frame=''>0 0 0 0 -0 0</pose>
          <geometry>
            <mesh>
              <scale>1 1 1</scale>
              <uri>/home/danil/ros_lib_ws/src/youbot_description/meshes/youbot_gripper/finger_convex.dae</uri>
            </mesh>
          </geometry>
          <max_contacts>10</max_contacts>
          <surface>
            <contact>
              <ode/>
            </contact>
            <bounce/>
            <friction>
              <torsional>
                <ode/>
              </torsional>
              <ode/>
            </friction>
          </surface>
        </collision>
        <visual name='gripper_finger_link_r_visual'>
          <pose frame=''>0 0 0 0 -0 0</pose>
          <geometry>
            <mesh>
              <scale>1 1 1</scale>
              <uri>/home/danil/ros_lib_ws/src/youbot_description/meshes/youbot_gripper/finger.dae</uri>
            </mesh>
          </geometry>
        </visual>
        <self_collide>0</self_collide>
        <enable_wind>0</enable_wind>
        <kinematic>0</kinematic>
      </link>
      <joint name='gripper_finger_joint_r' type='prismatic'>
        <child>gripper_finger_link_r</child>
        <parent>arm_link_5</parent>
        <axis>
          <xyz>-0.367852 -0.926495 0.079325</xyz>
          <limit>
            <lower>0</lower>
            <upper>0.0115</upper>
            <effort>1</effort>
            <velocity>0.1</velocity>
          </limit>
          <dynamics>
            <damping>1</damping>
            <friction>1</friction>
            <spring_reference>0</spring_reference>
            <spring_stiffness>0</spring_stiffness>
          </dynamics>
          <use_parent_model_frame>1</use_parent_model_frame>
        </axis>
      </joint>
      <plugin name='gazebo_ros_controller' filename='libgazebo_ros_control.so'>
        <robotNamespace>/</robotNamespace>
      </plugin>
      <plugin name='gazebo_grasp_fix' filename='libgazebo_grasp_fix.so'>
        <arm>
          <arm_name>arm_1</arm_name>
          <palm_link>arm_link_5</palm_link>
          <gripper_link>gripper_finger_link_l</gripper_link>
          <gripper_link>gripper_finger_link_r</gripper_link>
        </arm>
        <forces_angle_tolerance>100</forces_angle_tolerance>
        <update_rate>4</update_rate>
        <grip_count_threshold>4</grip_count_threshold>
        <max_grip_count>8</max_grip_count>
        <release_tolerance>0.005</release_tolerance>
        <disable_collisions_on_attach>0</disable_collisions_on_attach>
        <contact_topic>__default_topic__</contact_topic>
        <robotNamespace>/</robotNamespace>
      </plugin>
      <static>0</static>
      <plugin name='gazebo_grasp_fix' filename='libgazebo_grasp_fix.so'>
        <arm>
          <arm_name>arm_1</arm_name>
          <palm_link>gripper_palm_link</palm_link>
          <gripper_link>gripper_finger_link_l</gripper_link>
          <gripper_link>gripper_finger_link_r</gripper_link>
        </arm>
        <forces_angle_tolerance>100</forces_angle_tolerance>
        <update_rate>4</update_rate>
        <grip_count_threshold>4</grip_count_threshold>
        <max_grip_count>8</max_grip_count>
        <release_tolerance>0.005</release_tolerance>
        <disable_collisions_on_attach>0</disable_collisions_on_attach>
        <contact_topic>__default_topic__</contact_topic>
        <robotNamespace>/</robotNamespace>
      </plugin>
      <pose frame=''>1.7 0 0.2 0 -0 0</pose>
    </model>
    <model name='table_marble'>
      <static>1</static>
      <pose frame=''>0.20129 -0.036126 0.648 0 -0 0</pose>
      <link name='link'>
        <collision name='collision'>
          <geometry>
            <mesh>
              <uri>model:///table_marble/meshes/table_lightmap.dae</uri>
              <scale>0.25 0.25 0.25</scale>
            </mesh>
          </geometry>
          <max_contacts>10</max_contacts>
          <surface>
            <contact>
              <ode/>
            </contact>
            <bounce/>
            <friction>
              <torsional>
                <ode/>
              </torsional>
              <ode/>
            </friction>
          </surface>
        </collision>
        <visual name='visual'>
          <geometry>
            <mesh>
              <uri>model://table_marble/meshes/table_lightmap.dae</uri>
              <scale>0.25 0.25 0.25</scale>
            </mesh>
          </geometry>
          <material>
            <script>
              <uri>model://table_marble/materials/scripts</uri>
              <uri>model://table_marble/materials/textures</uri>
              <name>Table/Marble_Lightmap</name>
            </script>
            <lighting>0</lighting>
          </material>
        </visual>
        <self_collide>0</self_collide>
        <enable_wind>0</enable_wind>
        <kinematic>0</kinematic>
      </link>
    </model>
    <state world_name='default'>
      <sim_time>180 964000000</sim_time>
      <real_time>181 474051241</real_time>
      <wall_time>1620068842 738979136</wall_time>
      <iterations>180964</iterations>
      <model name='ground_plane'>
        <pose frame=''>0 0 0 0 -0 0</pose>
        <scale>1 1 1</scale>
        <link name='link'>
          <pose frame=''>0 0 0 0 -0 0</pose>
          <velocity>0 0 0 0 -0 0</velocity>
          <acceleration>0 0 0 0 -0 0</acceleration>
          <wrench>0 0 0 0 -0 0</wrench>
        </link>
      </model>
      <model name='table_marble'>
        <pose frame=''>0.485909 -0.223284 0.648 0 -0 0</pose>
        <scale>1 1 1</scale>
        <link name='link'>
          <pose frame=''>0.485909 -0.223284 0.648 0 -0 0</pose>
          <velocity>0 0 0 0 -0 0</velocity>
          <acceleration>0 0 0 0 -0 0</acceleration>
          <wrench>0 0 0 0 -0 0</wrench>
        </link>
      </model>
      <model name='youbot'>
        <pose frame=''>1.0876 -0.894035 0.997234 8e-05 0.000239 -0.067932</pose>
        <scale>1 1 1</scale>
        <link name='arm_link_1'>
          <pose frame=''>1.11157 -0.895673 1.09323 -2.8e-05 -0.00025 2.86407</pose>
          <velocity>0.001306 -0.000191 0.007234 6.4e-05 0.009638 -1.7e-05</velocity>
          <acceleration>-0.18941 -1.77331 16.2521 2.83594 -0.532788 3.01192</acceleration>
          <wrench>-0.456858 -4.27722 39.2 0 -0 0</wrench>
        </link>
        <link name='arm_link_2'>
          <pose frame=''>1.07984 -0.886635 1.11224 -5.6e-05 -1.13475 2.86413</pose>
          <velocity>0.002036 -0.000844 0.007754 0.002494 0.000442 -0.001313</velocity>
          <acceleration>1.15467 -4.98601 17.107 -2.87954 0.159965 -1.80547</acceleration>
          <wrench>1.33364 -5.75884 19.7586 0 -0 0</wrench>
        </link>
        <link name='arm_link_3'>
          <pose frame=''>1.21496 -0.925128 1.1777 -6.5e-05 1.30594 2.864</pose>
          <velocity>0.002283 0.000501 0.003142 -0.000633 0.013224 0.002536</velocity>
          <acceleration>0.47452 -3.59715 6.15095 2.07836 -0.667149 0.598405</acceleration>
          <wrench>0.443202 -3.35973 5.74499 0 -0 0</wrench>
        </link>
        <link name='arm_link_4'>
          <pose frame=''>1.08965 -0.88943 1.21303 6.2e-05 -0.455045 2.86404</pose>
          <velocity>0.002763 0.000483 0.000952 -0.017584 0.008993 0.003306</velocity>
          <acceleration>1.19286 -2.7012 0.846031 1.79767 0.593752 0.332948</acceleration>
          <wrench>1.04614 -2.36896 0.741969 0 -0 0</wrench>
        </link>
        <link name='arm_link_5'>
          <pose frame=''>1.14633 -0.905569 1.32892 -0.112129 0.441963 -0.534788</pose>
          <velocity>0.003998 0.002846 8.8e-05 -0.013666 0.015298 0.004829</velocity>
          <acceleration>0.158403 -1.51588 0.290961 -0.472911 -1.02721 1.38516</acceleration>
          <wrench>0.055599 -0.532072 0.102127 0 -0 0</wrench>
        </link>
        <link name='base_link'>
          <pose frame=''>1.0876 -0.894035 0.997234 8e-05 0.000239 -0.067932</pose>
          <velocity>0.000329 -4.6e-05 0.007433 0.001374 0.010117 3.8e-05</velocity>
          <acceleration>-0.119864 -0.38411 16.1618 1.21716 -0.901003 0.089819</acceleration>
          <wrench>-1.38623 -4.44223 186.912 0 -0 0</wrench>
        </link>
        <link name='gripper_finger_link_l'>
          <pose frame=''>1.17401 -0.903264 1.36742 0.11213 -0.441963 2.60681</pose>
          <velocity>0.004611 0.003498 -0.000504 -0.012939 0.01537 0.005024</velocity>
          <acceleration>0.441707 -1.71953 -0.08799 1.52811 -1.47228 1.30767</acceleration>
          <wrench>0.004417 -0.017195 -0.00088 0 -0 0</wrench>
        </link>
        <link name='gripper_finger_link_r'>
          <pose frame=''>1.16517 -0.919983 1.36934 -0.11213 0.441963 -0.534789</pose>
          <velocity>0.004715 0.003482 -0.000141 -0.01323 0.015349 0.004945</velocity>
          <acceleration>0.281661 -1.61011 0.012357 0.974752 -1.20311 1.33378</acceleration>
          <wrench>0.002817 -0.016101 0.000124 0 -0 0</wrench>
        </link>
      </model>
      <light name='sun'>
        <pose frame=''>0 0 10 0 -0 0</pose>
      </light>
    </state>
    <gui fullscreen='0'>
      <camera name='user_camera'>
        <pose frame=''>4.71879 -3.61738 2.53907 0 0.275643 2.35619</pose>
        <view_controller>orbit</view_controller>
        <projection_type>perspective</projection_type>
      </camera>
    </gui>
  </world>
</sdf>
